Workbook

Sheet Prospek 2026
B1: Prospek 2026 | C1: =SUM(C3:C90) -> 508090506620
A2: No | B2: Project Name | C2: Value excl. PPN | D2: Status | F2: CUSTOMER | G2: Desc | H2: Factory Promise | I2: Remarks Kontraktor | J2: Remarks Principle | K2: Remarks AI | L2: INSULATOR | M2: Remarks | N2: PIC | O2: Keterangan
A3: 1 | B3: PENGADAAN DAN PEMASANGAN INFRASTRUKTUR SISTEM PENGAMANAN DI WILAYAH UPT SEMARANG | C3: 5287458300 | K3: bidbiond pertama 8 jan - 6 jun ke-2 7 jun - 3 nov ke-3 3 nov - 2 april
A4: 2 | B4: Penggantian Earthwire SUTET 500kV Kembangan - Gandul Menjadi OPGW | C4: 8547877000
A5: 3 | B5: Penggantian Trafo ke 2 GI Cepu, dan Trafo ke 2 GI blora | C5: 11000000000 | K5: Terder Terbatas, 540 Hari Kerja, okt 2027
A6: 4 | B6: Perkuatan Sistem Proteksi Petir di Wilayah UPT Semarang | C6: 8600000000 | K6: Terder Terbatas, 260 Hari Kerja, okt 2026
A7: 5 | B7: Penggantian Earthwire Korosif di Wilayah UPT Semarang | C7: 16000000000 | K7: Tender Terbatas, 365 Hari Kerja, Maret 2027
A8: 6 | B8: Pengadaan dan Pemasangan V Insulator Akibat Andongan Rendah | C8: 13200000000 | K8: Tender Terbatas, 540 Hari Kerja, Sep 2027
A9: 7 | B9: Pengadaan dan Penggantian Sistem Proteksi di Wilayah UPT Semarang | C9: 4500000000 | K9: Tender Terbatas, 540 Hari Kerja, Sep 2027
A10: 8 | B10: Penanganan Anomali Midspan Joint Tersebar di Wilayah UPT Semarang | C10: 4700000000 | K10: Tender Terbatas, 365 Hari Kerja, April 2027
A11: 9 | B11: Penggantian CDE Tj Jati - Sayung | C11: 5700000000 | K11: Terder Terbatas, 365 Hari Kerja, April 2027
A12: 10 | B12: Penggantian Kabel Power dan Sealing End di GIS 150 kV Tambaklorok | C12: 24000000000 | K12: Terder Terbatas, 365 Hari Kerja, April 2027
A13: 11 | B13: Pengadaan Material OLTC GITET 500 kV Ungaran | C13: 6300000000 | K13: Terder Terbatas, 365 Hari Kerja, April 2027
A14: 12 | B14: Pengadaan Material Bushing 70kV | C14: 184000000 | K14: PL
A15: 13 | B15: Pengadaan Thermovisi | C15: 866000000 | K15: Terder Terbuka, 365 Hari Kerja, April 2027
A16: 14 | B16: Pengadaan Alat Uji Kadar Air dan PDKB | C16: 2800000000 | K16: Terder Terbuka, 365 Hari Kerja, Mei 2027
... A45: 43 | B45: Grounding UPT Bogor | C45: 5000000000 | K45: Terder Terbuka
A46: 44 | B46: PENGADAAN BARANG DAN JASA KONSTRUKSI SUTT 150 KV PEMECUTAN KELOD -TX. PESANGGARAN -TX. BANDARA / NUSA DUA (SECTION SUTT 150 KV TX. PESANGGARAN - NUSA DUA 1 -2 | C46: 3376418010 | F46: KSO PT. JAMPA INDOTAMA - PT. ALHAS JAYA GROUP
A47: 45 | B47: PENGADAAN BARANG DAN JASA KONSTRUKSI SUTT 150KV PEMECUTAN KELOD - TX. PENSANGGARAN - TX. BANDARA / NUSA DUA (SECTION SUTT 150KV PEMECUTAN KELOD (TX. PESANGGARAN) - TX. BANDARA DAN SUTT 150 KV PESANGGARAN - TX. BANDARA) | C47: 4500000000 | F47: PT GRIDTECH INDONESIA
C48: =SUM(C3:C47) -> 254045253310

Sheet Prospek 2025
B1: Prospek 2025 | C1: =SUM(C3:C86) -> 106686480886
A2: No | B2: Project Name | C2: Value excl. PPN | D2: Status | F2: CUSTOMER | G2: Desc | H2: Factory Promise | I2: Remarks Kontraktor | J2: Remarks Principle | K2: Remarks AI | L2: INSULATOR | M2: Remarks | N2: PIC | O2: Keterangan
A3: 1 | B3: Pengadaan Isolator Tersebar di UPK Bangka Belitung | C3: 975424000 | F3: Indodaya Naratama Abadi | K3: sdh ttd kontrak berlaku sampai 17 September, perpanjang jampel 180 hari sampai tgl 22 Feb 2026, surat jalan sudah tanggal 09/12, BA sudah dikerjakan, info pencairan Februari, BAP belum infonya di Februari
A4: 2 | B4: PEKERJAAN PEMBANGUNAN GITET 275/150 KV WOTU EXTENSION | C4: =479141500+361307000 -> 840448500 | F4: Kelinci Mas Unggul | K4: FU ke Emmy bagian tender ke pak syuaib bagian project belum ada update, pengumuman pememang tgl 29/09/25, stringset dan connector pakai material stock dari projek Wotu sebelumnya, perlu diagendakan ke KMU Makassar
A5: 3 | B5: PEMBANGUNAN TRANSMISI 150 KV PAKNING- SIAK: LOT 1&2 | C5: =D5 -> 14966403554 | D5: =5682983898+9283419656 -> 14966403554 | E5: Sumatra BAP Percie, NPC, Multifab,Citramas, Bukaka dan Twink | F5: Sapta Guna Utama PT, Berca Buana Sakti PT | I5: penjelasan 3 Agustus 2023, closing 13 September 2023 | K5: kita sdh supprt Closing 23 Des (diundur 21 Jan 25), mereka pakai hogn dan KAK LOT1&2 harga kita sudah paling murah mbak laely di Pantau lagi April 28, mundur 12/01 | N5: Marul
A6: 4 | B6: PEMBANGUNAN TRANSMISI 150 KV TANAH GROGOT - SEI DURIAN LOT: 1&2 | C6: =8830659545+9025675355 -> 17856334900 | D6: 6933786700 | E6: Kalimantan BAP NPC,citramas (tdk ikut), Citicon, WST, Twink, Citac, Tinakana | F6: Distraco, PT, PT. Citicon Adhinugraha | I6: penjelasan 2 Agustus 2023, closing 14 September 2023 | K6: Closing 19 Maret sdh diberikan penawaran, masih menunggu update, Closing 29 des, SGU Citicon, Distraco, mundur 12/01 | N6: Laely
A7: 5 | B7: PEMBANGUNAN TRANSMISI 150 KV SEI DURIAN - TARJUN LOT: 1&2 | C7: =8365887990+8550639810 -> 16916527800 | E7: BAP Distraco, Citicon, Bukaka, Multifab, Sangkan | F7: PT. Nusantara Power Construction, PT. Citicon Adhinugraha | K7: Closing 19 Maret sdh diberikan penawaran, masih menunggu update, Closing 29 des, SGU Citicon, Distraco, mundur 12/01 | N7: Laely
A8: 6 | B8: UPRATING TRAFO 1 GI 150 KV BUMI SEMARANG BARU | D8: 9600000000 | E8: 1. 9.672.721.037,00 (HPS), 2. tgl kontrak 21 Oktober 2024 semua material percepatan sdh clear, material yg lain di PO tgl 30 des kecuali MK, GS, CCTV, menunggu approval dwg dan WP, | F8: KSO KSCM - INA | J8: garansi material: ERI sdh ada namun scan aslinya ngambil di cikarang (x), Enindo blm ada (x), KMI baru cek draft (x), Putra nata asli (v), amptron asli (v) GTS Panel (x) | K8: kontrak sampai 29 november 2025 pemeliharaan 6 bulan sampai 30 mei 2026 , VIP termin 3 sudah dibayar 24/11, pending item: pekerjaan DFR dan AVR akan dilaksanakan di masa pemeliharaan,
A9: 7 | B9: PENGADAAN DAN PENGGANTIAN ISOLATOR DI UIT JBM | C9: 4247984850 | D9: Menunggu harga ACCC dari PLP berikut diskon finalnya | F9: PT KENCANA ALAM PUTRA | K9: SOA tgl 21 November minta list mana yang urgent terlebih dahulu sdh dikirim, sudah FAT, pengambilan parsial I tgl 2 okt ada permintaan list material selesai di 20 okt, pengambilan parsial ke-II di tgl 24 okt, parsial ke-III sudah diambil tanggal 26, kekurangannya est tgl 20/12 poin C item 1-15, poin D item 1-3, poin E 1-12, poin F item 1, poin G item 1, poin H item 1, poin I item 1-2, paling lama 21/03/2026, kalau pakai jalur udara lebih cepat 1 bulan bayar 15 juta, info dari PLP akan mengirim item yang sudah selesai
A10: 8 | B10: REVITALISASI GIS DI UNIT INDUK TRANSMISI JAWA BAGIAN TIMUR DAN BALI (OVERHAUL GIS SAWAHAN | C10: 372000000 | F10: PT. High Volt Technology | K10: DP sudah dibayar tgl 27 sept SOA Connector 27 okt material connector sudah digudang ugc tgl 29/10 menunggu pengambilan, SOA Insulator July 2026, insulator sdh di PO ulang ke PLP SOA (1 Juni)
A11: 9 | B11: PENGADAAN DAN PEMASANGAN INFRASTRUKTUR SISTEM PENGAMANAN DI WILAYAH UPT SEMARANG | D11: 5287458300 | E11: pinjam MASATEK note di isian kualifikasi minta situlis subcon indodaya | F11: PT. Indodaya Naratama Abadi | K11: bidbiond pertama 8 jan - 6 jun ke-2 7 jun - 3 nov ke-3 3 nov - 2 april
A12: 10 | B12: UPRATING 2 DIAMETER DI GISTET SURALAYA ARAH CILEGON | C12: 303313050 | F12: KSO PT. Kencana Alam Putra - Enindo Orbitama | K12: SOA 26 November, material di gudang Alam diambil Januari, 05/01 FU ke pak Eko
B13: PROJEK SURALAYA PENGGANTIAN TENSION DEAD END | C13: 35766810 | F13: PT. High Volt Technology | K13: dibayar tanggal 5/12, diambil Januari
A14: 12 | B14: PENGADAAN STRINGSET PROJECT WK ROKAN PAKET -A | C14: 227069038 | F14: PT. PLN Nusantara Power Construction | K14: revisi invoice sudah dikirim, material sudah masuk ke gudang tgl 27/11, kekurangan BA sudah dikirim tanggal 11/12, 05/01 FU ke Pak Irwan
A15: 14 | B15: PENGGANTIAN TRAFO #3 150/20 KV 60 MVA GI CENGKARENG DALAM RANGKA PENGGANTIAN TRAFO KONDISI BURUK DI UPT DURIKOSAMBI | C15: 20211800 | F15: PT Indevco Global | K15: indevco menang, menunggu pembayaran post insulator, invoice dikirim tgl 23/12
A16: 15 | B16: PENGGANTIAN CT 500 KV P0 DI WILAYAH UPT BEKASI | C16: 147385728 | F16: Duta Cakrawala indonesia, PT | K16: Menang, Baru ttd kontrak, Belum ada jadwal nanti diinfokan kemajuan time line, segara rilis PO dan akan dikabari, selain pakai PLP pakai KAK, sedang proses approval minggu ini, kontrak panjang menunggu CT belum dirilis PO masih dalam proses, info dari pak Hary belum. Planing Pekerjaan, menunggu CT On site FU 14 nov, sudah bertemu pak Hari 17/12
A17: 16 | B17: PEKERJAAN PEMBANGUNAN GI 150 KV SEBUKU NEW 30 MVA | C17: 969108200 | F17: PT PLN NUSANTARA POWER CONSTRUCTION, | K17: NPC MENANG, qty nya berkurang 70%, sudah kirim quote terbaru ke NPC,
A18: 17 | B18: PENYELESAIAN PENDING ITEM GI DAN TRANSMISI DALAM RANGKA STOP/STAP/STP PROYEK WILAYAH UPP JBT 4 | C18: 833387400 | F18: PT, Pas Jaya Mandiri | K18: Closing 25 Mei, PJM sdh menang, (Section 1 Amsak), (Section 2 Multifab), (Section 3 Citacontract), kontrak akhir menunggu update harga PLP,sdh approved sdng disiapkan kebuuthan materialnya apa saja UIP FU terakhir 01/12 ke pak Albert Markus menunggu BOQ dari PLN
A19: 18 | B19: PEMBANGUNAN GI 150 KV KTT INDORAMA BESERTA SUTT 150 KV KTT INDORAMA – INC (PADALARANG – JATILUHUR) | C19: 2337683607 | F19: PT. MULTI FABRINDO GEMILANG | K19: GI menggunakan KAK, menunggu diskon dari PLP 22/12, menunggu harga diskon dari Alam, terakhir upload di eproc multifab tanggal 31/12, request diskon ke PLP 27%, request diskon ke DEM 10%
A20: 19 | B20: PENGADAAN DAN PEMASANGAN MTU PO DI UIT JBB LINGKUP JASA PEMASANGAN MTU PO DI UPT CIKUPA | C20: 99450000 | F20: PT. Garda Perdana Security | K20: menang, sudah ttd kontrak, sedang kick of meeting, info rencana survey di bulan desember, jeko FU 12/12 sedang proses survey, FU 18/12 tidak ada respon, dijadwalkan silaturahmi w2 januari
A21: 20 | B21: PEMBANGUNAN TRANSMISI 150 KV CIKUPA NEW - INC. (TERMASUK 2 TOWER TX JATAKE - JATAKE) (PENGADAAN ULANG) | C21: 793576000 | D21: 38124351880 | F21: KSO SAJ TKAD | K21: sudah lunas, kemungkinan FAT Januari, tanggal 13 Januari FAT menunggu konfirmasi dari SAJ
A22: 21 | B22: TENDER ULANG PEKERJAAN PEMBANGUNAN EXTENSION 1 TRAFO BAY+TRAFO 30MVA GARDU INDUK 150KV SATUI | C22: 218213900 | D22: 30496332477 | F22: PT Citra Bakti Persada | K22: sdh ngasih harga menunggu update PLN Site, sdh minta dukungan, menunggu update site terakhir FU tgl 01/12, order via infotech, IAG beli ke infotech
A23: 22 | B23: PENGADAAN DAN PENGGANTIAN BUSHING P0 FASA R BAY 150/20 KV TRAFO#2 GI GANDAMEKAR DAN FASA S BAY 150/20 KV TRAFO#3 GI JABABEKA | C23: =D23*3% -> 20985150 | D23: 699505000 | F23: PT. ENINDO ORBITAMA | K23: masih proses approval dan masih proses produksi bushing, masih menunggu hasil survei, tgl 27 info dari user menunggu kedatangan barang, kemungkinan awal tahun 2026
A24: 23 | B24: PENGADAAN DAN PENGGANTIAN BUSHING TERSEBAR DI WILAYAH UPT BANDUNG | C24: =D24*3% -> 55869420 | D24: 1862314000 | F24: PT. ENINDO ORBITAMA | K24: masih proses approval estimasi sept - okt datangnya material bushing, tgl 27 info dari user menunggu kedatangan barang kemungkinan awal tahun 2026
A25: 24 | B25: PEMBANGUNAN TRANSMISI 150 KV TUBAN – PACIRAN SEKSI 1 & 2 | C25: =6460927340+6178468898 -> 12639396238 | E25: Seksi 1 Sangkan, Multifab, Indisi, WST, Seksi 2 Sangkan, HKP, Hasta Praja | F25: PT. Nusantara Power Construction, Indisi | K25: Closing 29 des, FU 04/11 BAP Sangkan, WST (sedang cari pasangan), HP, Indisi (ditolak sama plp), HKP (tdk ikut karna sudah yang punya), diundur 12/01 | N25: Marul
A26: 25 | B26: GITET BALARAJA | C26: 39366000 | F26: PT. ENINDO ORBITAMA | K26: masih proses approval dan masih proses produksi bushing, menunggu GIS sekitar 8 bulan lagi kemungkinan awal tahun 2026
A27: 26 | B27: PENGADAAN PEKERJAAN PEMBANGUNAN BAY COUPLER GARDU INDUK PARINGIN | C27: 251499948 | F27: PT. ENERGI ENTELEMI INDONESIA | K27: menang, verifikasi kontrak, sedang direview tim purchasing dan project untuk list supplier dan vendor penawaran harga sesuai kebutuhan kontraktor sdh dikirim dan direview oleh kontraktor, FU 05/01 pak Alvin minta waktu ketemu
A28: 27 | B28: PENGADAAN DAN PENGGANTIAN SEALING END GIS 150 KV UPT CAWANG TAHAP 2 | C28: 26190000 | F28: PT. SANTOSA ASIH JAYA | K28: Menang, FU 09/12 projek tahun depan
A29: 28 | B29: PENGGANTIAN SKTT 150 KV PEGANGSAAN – WAHANA | C29: 41973000 | F29: PT. SANTOSA ASIH JAYA | K29: Menang, FU 09/12 projek tahun depan
A30: 29 | B30: PENGGANTIAN MTU P0 WILAYAH UPT PURWOKERTO TAHUN 2025 | C30: 14956600 | F30: PT. GARDA PERDANA SECURITY | K30: menang, on site awal bulan desember, FU jeko terakhir 12/12 belum ada update lagi, jeko FU 19/12 tidak ada respon
A31: 30 | B31: JASA PENGGANTIAN MTU BOTTLENECK DI UPT GANDUL | C31: 345816000 | F31: PT SIMBARHOL TEKNIK PERKASA | K31: menang, sdh mulai pek. Gudang terlebih dahulu, FU terakhir 02/12 masih mengerjakan pekerjaan sipil (gudang) material MTU kemungkinan onsite tahun depan, jeko FU 19/12
A32: 32 | B32: EPC Poigar-2 HEPP Contactor BIDDING (2x15MW) / Pelelengan Kontraktor EPC PLTA Poigar-2 (2x15MW) | C32: =885100+55584000 -> 56469100 | D32: karena harga satuan | F32: PT Berca Buana Sakti | K32: closing 19/09 sdh dikirim ke BBS harganya, Pak Marul FU 18/08, tender EPC kontrak 6 bulan - 1 tahun
A33: 33 | B33: PENGADAAN DAN PENGGANTIAN TRAFO KONDISI BURUK WILAYAH TIMUR UITJBB LINGKUP JASA PENGGANTIAN TRAFO KONDISI BURUK DI GI CITRA HABITAT | C33: 55545000 | F33: PT DUTA CAKRAWALA INDONESIA | K33: menang sdh ttd kontrak, nabil FU ke pak Veri dan pak Abroham 01/12, pak Abroham tanya ke pak Veri tapi belum ada approval masih dalam tahap survey
A34: 34 | B34: PENGADAAN DAN PENGGANTIAN POLA PROTEKSI TERSIER IBT DI UPT MALANG | C34: 21495000 | F34: PT PAS Jaya Mandiri | K34: proses approval TPG, jeko FU 05/12 ke pak Eko nanti dikabari jika akan PO, FU 05/01 jeko
A35: 35 | B35: STRINGSET PURUK CAHU SECTION 1 | C35: 1990941480 | F35: KSO KE AMSAK | K35: kontrak PLN Kalbar, sdh penawaran harga ke kontraktor, Marul FU ke Pak Anrizal
A36: 36 | B36: Insulator GIG Puruk Cahu Sec 1 | C36: 1234440000 | D36: sudah dengan pengiriman | F36: KSO KE AMSAK | K36: kontrak PLN Kalbar, Marul FU ke Pak Anrizal
A37: 37 | B37: Relokasi Tower Cibatu | C37: 639294000 | F37: PT. Jaring Rainan Hutama | K37: sudah 100% pembayaran alam sdh PO ke PLP SOA line 1 dan 6 tanggal 16/01 sisanya 22/12, menunggu revisi ITP dan FAT, menunggu jadwal FAT test dari PLP
A38: 38 | B38: Relokasi Tower Jonggol | C38: 50401508 | F38: CMS | K38: Pak Asep proses DED & BED terakhir update 15/10, closing 12/09, estimasi project agustus sampai september 2026, laely FU 08/12 atau 09/12
A39: 39 | B39: BUKIT INDAH TL 150 KV | C39: 1910248200 | F39: PT. Nusantara Power Construction | K39: sudah pemasukan pembukaan sampul internal dari EPC swasta kemungkinan Februari 2026,
A40: 41 | B40: PEKERJAAN PENGADAAN DAN PEMASANGAN EXTENSION BAY TRAFO 4 DI GI 150 KV KUDUS | C40: 340573700 | F40: PT. AMSAK BANGUN PERSADA, | K40: Closing 04/09, Menang, menunggu approval drawing dan PO, sudah ada diskon PLP, 30-31/12 konsiyering AMSAK dan PLP di GI kudus
...

Sheet Progress 2024
B1: Progres 2024 | C1: =SUM(C3:C6) -> 2457867693
A2: No | B2: Project Name | C2: Value excl. PPN | D2: Status | F2: CUSTOMER | G2: Desc | H2: Factory Promise | I2: Remarks Kontraktor | J2: Remarks Principle | K2: Remarks AI | L2: INSULATOR | M2: Remarks | N2: PIC | O2: Keterangan
A3: 1 | B3: Perbaikan Anomali Jaringan di UPT Bandung | C3: 475955700 | D3: Sudah PO | E3: sisa | F3: PT. Cipta Daya Utama | K3: cicilan pertama 7 Desember 25.000.000, sisa utang 344 Jt, cicilan kedua Januari 2025 sebesar 50 jt, sisa 214 jt, CDU akan bayar setiap tgl 25 sebesar 50jt, 28 Feb 30 jt, 28 mei bayar 50 jt sisa 164jt, janji bayar 27 Juni, 30 juni bayar 30jt sisa 134 jt, info dari Pak Sudaryo, bulan ini akan melakukan pelunasan ke PT Alam di minggu ke 4. Untuk tanggal pasti pembayarannya belum ada update terbaru lagi, 04/08 dibayar 54 jt sisa 80 jt, sisa 49.999.982, terakhir bayar 29 Agustus 30.817.597
A4: 2 | B4: JASA PENGGANTIAN KAWAT GSW BERIKUT STRINGSETNYA PADA SUTET 500 KV BANDUNG SELATAN - NEW UJUNG BERUNG T.34-80, SUTT 150 KV PADALARANG BARU - CIRATA T.01-T.26, DAN BANDUNG SELATAN - KIARACONDONG T.50-T.62 | C4: 339839820 | D4: 1.931.400.000 (Nilai Kontrak) sdh dicicil 50jt sisa 289.839.820 mega sudah mengajukan VIP sejak tgl 14 Feb | E4: amandemen s/d 2 January 530 hari sdng pengajukan perpanjangan 90 hari s/d 2 april 25 mulai kerja feb sdh dicicil 50jt, yg blm pdlrng - cirata T12 -22 Bansel - Uber T.34 - 50 akan di kerjakan feb, ada jadwal padam lagi 11-12 Jan pdlng baru - cirata line 1 18-19 jan bansel-new uber, minta dicicil | F4: KSO Mega Alfarizki - Indodaya Naratama Abadi | K4: BAST sudah dikirim dibulan Januari Pengajuan restitusi di bulan april estimasi 3 - 4 bulan sampai dengan agustus. Sudah FU bulan Juni, masih on process. Akan di FU kembali ke MA pada bulan Juli, masih restetusi 32jt (perkiraan agust), belum cair FU Bu diyah tgl 4/08 | M4: Kontrak 23 Juni 2023 masa berlaku kontrak 365 hari, pekerjaan dimulai 27-28 January dan 3-4 Feb 2024 ada kendala GSW putus di tower 50 (Bandung Selatan - New Uber), 22 Jan pekerjaan unclamping dari tower 34 - 62 (ada 4 tim), dan 22 jan haspel dan repair sleeve proses , Pemadaman 22 April - 25 April dan 29 April - 2 Mei 2024 T. 58-62, renc. tgl 22 pekerjaan di T. 58, 50, 51, 55 unclamping, tgl 11-12 T.12-T. 21 terakhirnya 18-19 Mei T. 24 - 26, rencana padam ganti GSW T. 1 - T. 22 PDRU Cirata Line1 22-23 juni line 2 T.1-T.22 29-30 Juni T.24-T.26 Cirata Line 6 Juli Line T.24-T.26 7 Juli, pasar steger pdlrng - cirata T.1-T.22, sdng proses pek. T.72-80 new Uber,06/02/2025 final quantity, BAST sudah Januari
A5: 5 | B5: Retender GSW 500 KV UPT Bogor | C5: 1642072173 | D5: 5685626000 | E5: Saguling - cibinong T.21&22 - T.38, T.111 - 139 sdh selesai blm ada jadwal lagi, update terakhir pekerjaan 75% | F5: Konsosium Mega Alfarizki - Indodaya Naratama Abadi,PT | I5: Closing tgl 23 Agustus 2023 | K5: menunggu jadwal padam jalur Cilegon. Penagihan mega sudah termin 2 dari mega pengen minta perhitungan PPH dan fee admin seperti perhitungan project bandung, sdh bayar 200jt tgl 5 Juni. FU tanggal 14 koordinasi dlu ke bagian finance, sisa termin 1 dan termin 2 sisa 269jt total tagihan PO 848jt | M5: kontrak tgl 25 September 2023, pelaksanaan 720 hari sejak kalender, barang sudah disite semua dan sdh pemeriksaan barang tgl 11 Jul, rencananya dit. Kapan jadwal padam 29 Jul - 16 Agus tetapi MAnya msh blm ada konfirmasi 24 Jul, ada usulan tgl 2-6 des, 9-13 des. Jalur saguling - cibinong, 18-19 dan 25-26 jan 2025 jalur cilegon - cibinong bln feb saguling cibinong 2, tgl 19 jadwal padam cibinong-saguling 8-17 des line 1, saguling cibinong 2 T134-T.152 tgl 3-7 feb, tgl 8-9 feb Cilegon-cibinong , tgl 10-14 feb saguling-cibinong 2, tgl 17-21 saguling-cibinong 2, tgl 24-28 saguling-cibinong 2
A6: 7 | B6: PENGADAAN DAN JASA PENGGANTIAN KABEL 66 KV TERSIER IBT 2 GITET UNGARAN | D6: 6184864900 | E6: kontrak tgl 25 Jun - 25 Feb 2025, FAT sdh & Material sdng dikirim datang sekitar 2 des dipick up masatek | F6: UPT Semarang | G6: KSO Masatek - INA, menunggu klarifikasi sampul 1 | K6: kabel sdh datang di GI Ungaran, Jumat 1 Nov meeting dgn pak ayub membahas sipil, sealing end trimitra tdk jadi thn ini luncur ke tahun depan, masih direview BOQ Sipil kerja (+-), sealing end sdh sampai mulai kerja ditgl 9 - 31 jan, supervisi arkasil di tgl 1-12 maret, EOT Prafinal Quantity sampai sekarang pekerjaan 70%, menunggu pek. MTU dari induk estrimasi bln agustus, pak ayub : aspal sdh dikerjakan dan penambahan linkbox bobot sekitar 92%, sdh bayar termin 2 tgl 11/07 560jt tanpa PPN, termin 3 sdh dibayar tgl 27/09 543jt

Sheet Progress 2023
B1: Progres 2023 | C1: =SUM(C3:C28) -> 56442386959
A2: No | B2: Project Name | C2: Value excl. PPN | D2: Status | F2: CUSTOMER | G2: Desc | H2: Factory Promise | I2: Remarks Kontraktor | J2: Remarks Principle | K2: Remarks AI | L2: INSULATOR | M2: Remarks | N2: PIC | O2: Keterangan
A3: 1 | B3: PEMBANGUNAN TOWER RELOKASI TRANSMISI AIR ANYIR - PANGKALPINANG LINTASAN SUNGAI BATU RUSA | C3: =288802500+344822400 -> 633624900 | D3: Sudah PO | F3: PT Tesla Daya Elektrika | K3: pekerjaan addendum sampai maret 2024, sudah PO INA ke Sicame untuk stringset, insulator tidak jadi di PO ke INA karna tidak ready stock, sudah DP 20%, menunggu update sicame | M3: Selasa Adel Fu kontraktor lagi | N3: Adel
A4: 2 | B4: JASA PEMASANGAN MTU DAN PENGADAAN ALAT UJI DI WILAYAH UPT SEMARANG | C4: 214722900 | F4: PT. Global Twin Star | K4: Pemenang Tender, Menunggu PO & approval drawing dari kontraktor, baru ttd kontrak 20 Nov 2023, update tgl 15 info dari GTS pakai eksisting | L4: 270
A5: 3 | B5: Perbaikan Anomali Jaringan di UPT Bandung | C5: 475955700 | D5: Sudah PO | F5: PT. Cipta Daya Utama | K5: cicilan pertama 7 Desember 25.000.000
A6: 4 | B6: Pengadaan dan Jasa Penggantian String Set serta Isolator 120 kN untuk SUTT 150kV Purbalingga - Rawalo T.94-172 | C6: 3186135459 | D6: Sudah PO | F6: Perintis Sarana Elektrik, PT | G6: Pengadaan dan jasa | I6: Pembayaran Back to back | J6: Minta penawaran harga terbaru | K6: menunggu retensi 5%, 176.830.518, BAST 22 Mei 2023 Retensinya Mei 2024 | M6: PO Perintis Back to Back, INA sudah DP 20% ke Sicamindo, Material siap di pick up minggu ke 3 Desember 2022 di balaraja oleh kontraktor | O6: Pastikan material selesai kapan.
A7: 5 | B7: JASA PENGGANTIAN KAWAT GSW BERIKUT STRINGSETNYA PADA SUTET 500 KV BANDUNG SELATAN - NEW UJUNG BERUNG T.34-80, SUTT 150 KV PADALARANG BARU - CIRATA T.01-T.26, DAN BANDUNG SELATAN - KIARACONDONG T.50-T.62 | C7: 339839820 | D7: 1931400000 | F7: KSO Mega Alfarizki - Indodaya Naratama Abadi | K7: Kontrak 23 Juni 2023 masa berlaku kontrak 365 hari, PO pertama repair sleep sudah ready, PO ke Sicame (midspan joint as 70, vibration damper,armour rod dan shackle), jadwal pekerjaan dimulai 13-14 January dan 27-28 January (Bandung Selatan - New Uber) haspel sewa gudang sampai 12 January 2024, material 150kV masih disortir
A8: 6 | B8: JASA PENGGANTIAN ISOLATOR BERIKUT STRINGSET DI T.1 S/D T.54 SUTT 70KV PURWAKARTA – KOSAMBI BARU – SOUTH PASIFIC | C8: 1017196840 | D8: UPT Karawang INA tidak bisa konsorsium dikarenakan tidak punya pengalaman | E8: harga diatas sudah termasuk diskon kerawang dan semarang masing" 5% | F8: PT MEGA ALFARIZKI | K8: Sudah DP 10%, SOA 19 Jan 3 item sudah diambil tgl 11 Des GIRO 30 January 2024, sisanya 21 Des sudah diambil
A9: 7 | B9: JASA PENGGANTIAN EARTH WIRE BERIKUT STRINGSETNYA PADA SUTT PANDEANLAMPER – PUDAKPAYUNG T. 14-33 DAN SUTT TAMBAKLOROK-UNGARAN T.29-45 SERTA JASA PENGGANTIAN STRINGSET TOWER SUTT TAMBAKLOROK-UNGARAN T.01-12 AKIBAT KOROSI | C9: 579778800 | D9: UPT Semarang | F9: PT MEGA ALFARIZKI | K9: DP sudah 10% SOA 8 Desember sudah diambil tgl 11 Des, GIRO 30 January 2024
A10: 8 | B10: PEMBANGUNAN TRANSMISI 150 KV PAKNING- SIAK: LOT 1&2 | C10: 12211780546 | E10: Sumatra | F10: Sapta Guna Utama, PT | I10: penjelasan 3 Agustus 2023, closing 13 September 2023 | K10: Aanwijzing tanggal 21 Juli 2023, Closing 15 Desember 2023
A11: 9 | B11: PEMBANGUNAN TRANSMISI 150 KV SEI DURIAN - TARJUN: LOT 1&2 | C11: 15948442300 | E11: Kalimantan | F11: Distraco, PT | I11: penjelasan 2 Agustus 2023, closing 14 September 2023 | K11: 17 Januari pembukaan sampul 1
A12: 10 | B12: PEMBANGUNAN TRANSMISI 150 KV TANAH GROGOT - SEI DURIAN LOT: 1&2 | C12: 6933786700 | E12: Kalimantan | F12: Distraco, PT | I12: penjelasan 2 Agustus 2023, closing 14 September 2023 | K12: 17 Januari pembukaan sampul 1
A13: 11 | B13: Retender GSW 500 KV UPT Bogor | C13: 1642072173 | D13: 5685626000 | F13: Konsosium Mega Alfarizki - Indodaya Naratama Abadi,PT | I13: Closing tgl 23 Agustus 2023 | K13: kontrak tgl 25 September 2023, pelaksanaan 720 hari sejak kalender, asli kontrak sudah diterima jampel sudah diterima PLN sedang proses approval drawing sudah nen menunggu PO dari mega INA PO ke Sicame, euis FU 18 Des
A14: 12 | B14: GI Batu Raja Stringset | C14: 272252800 | E14: Sumatra | F14: Masatek | I14: Penawaran harga&drawing hari ini tgl 21 Agustus 2023 | K14: revisi drawing dan harga sudah dikirim ke kontraktor FU 21 Nov 2023
A15: 13 | B15: GI Batu Raja Insulator | C15: 177514000 | E15: Sumatra | F15: Masatek | I15: Sudah PO, alam belum PO ke DALIAN | K15: Insulator Laely PO Hari ini, sudah DP 20%
A16: 14 | B16: DIES AI DI Mega Tech | K16: Pengambilan direncanakan minggu ini
A17: 15 | B17: 2X25MWP BALI SOLAR PV CONSTRUCTION AND INSTALLATION 150KV TRANSMISSION LINE PT. Medco Solar Bali Barat | C17: =858542720+1026788400 -> 1885331120 | F17: Niagamas Setia Usaha,PT | I17: Masih proses evaluasi dan teknis, Closing tgl 28 Juli 2023 | K17: Closing 2 Agustus 2023, pembukaan sampul 1, belum ada keputusan dari medco, FU tgl 11 Desember
A18: 16 | B18: 2X25MWP BALI SOLAR PV CONSTRUCTION AND INSTALLATION 150KV TRANSMISSION LINE PT. Medco Solar Bali Timur | C18: =315601552+417879000 -> 733480552 | F18: Niagamas Setia Usaha,PT | I18: Masih proses evaluasi dan teknis, Closing tgl 28 Juli 2023 | K18: Closing 2 Agustus 2023, pembukaan sampul 1, belum ada keputusan dari medco, FU tgl 11 Desember
A19: 17 | B19: PENGADAAN DAN PEMASANGAN 1 BAY REAKTOR 30 MVAR | C19: =144762500+125820000 -> 270582500 | F19: Lembah Sentral Elektronindo, PT | I19: sudah PO ke PLP kontraktor minta minggu ke 3 February | K19: paling lambat oktober delivery maret 2024, terakhir kontraktor minta bulan febuari 2024 alam sudah komunikasi dengan pak tengku SOA 12 February 2024 sudah dp 20%
A20: 18 | B20: Penyempurnaan instalasi gedung dan perlengkapan K3 GIS Penggilingan II dalam rangka penyelesaian pending STP | C20: 232113950 | F20: PLN UPT Pulogadung | I20: sisil nunggu scan BA dari UPT baru di upload ke VIP | K20: kontrak tgl 13 nov 2023, sudah submit tgl 10 Desember 2023, dana ditahan UIP upload di VIP jadi January 2024 (Kekurangan BAP)
A21: 19 | B21: DESAIN, SUPLAI DAN PEMASANGAN GITET 500 KV KALIPURO | C21: 5982203000 | F21: PT. WIJAYA KARYA (Persero) Tbk | I21: Mbak Laely temui kontraktor | K21: Closing tgl 21 November 2023, Klarifikasi Teknikal disamakan dengan permintaan PLN, klarifikasi ke 2 sudah dikirim tgl 11 Des menunggu evaluasi sampul 1
A22: 20 | B22: Jasa EPC Pembangunan Gardu Induk 150kV untuk Penyambungan Tenaga Listrik PLN ke UBPN Kolaka | C22: 978017535 | F22: PT. High Volt Technology | I22: Sudah PO Menunggu approval drawing dari Antam | K22: Sudah PO, revisi Approval Drawing, minggu ini ada agenda zoom meeting (PLP. HVT, Antam), FU tgl 18 Des, Menunggu DP, setelah DP akan di PO ke PLP
A23: 21 | B23: JASA PENANGANAN ANOMALI JARINGAN DI WILAYAH UPT KARAWANG TAHUN 2023 | C23: 7005400 | F23: PT MEGA ALFARIZKI | I23: FU minggu ini apakah sudah ada kebutuhan KHS-nya | K23: FU 11 Des 2023, Kapan kebutuhannya
A24: 22 | B24: PENGGANTIAN CELL KAPASITOR 50MVAR DI GI 150KV KALIWUNGU | C24: 50000000 | D24: UPT Semarang | F24: Masatek | I24: Klarifikasi Harga | K24: Closing 22 November 2023
A25: 23 | B25: Pembangunan GI 150kV Tanggeung / Cianjur Selatan | C25: 600000000 | F25: PT. Buanareksa Binaperkasa, Mega Power | I25: masih evaluasi sampul 1 | K25: Mega Power menang, kami masih blm evaluasi vendor2 yg mendukung
A26: 24 | B26: UPRATING 2 LB GI 150 kV LAMONGAN BAY CERME 1,2 | C26: 377296766 | F26: PT. Global Twin Star, PT. Bina Buana Sewaka, PT Masatek | I26: Pemenang tender GTS | K26: GTS Menang, sudah dikirim ke kontraktor design baru stringset tanpa arching horn
A27: 25 | B27: Pekerjaan rekonfigurasi GIS Tandes TL Bay Ujung ke PKB #l dan TL Bay Perak ke PKB #2 | C27: 292034400 | E27: 775758900 | F27: PT. Mahakaam Jaya Sejahtera | I27: baru akan proses CDA lalu ttd kontrak | K27: Pemenang tender 6.185.031.000 FU 27 Nov, masih proses CDA
A28: 26 | B28: UPRATING LINE BAY GI 150KV BABAT DAN GI 150KV LAMONGAN | C28: 1401218798 | F28: PT. Global Twin Star | I28: Insulatornya ABI Stringsetnya PLP, masih menunggu klarifikasi teknikal | K28: Klarifikasi sampul 1
A29: 27 | B29: Pengadaan material untuk pemeliharaan di wilayah UPT Bogor | C29: 2318307208 | F29: PT. Indodaya Naratama Abadi | I29: Closing 12 Desember, Jumat 8 harus sudah selesai semua | K29: Closing 12 Desember, masih evaluasi sampul 1 INA DML Trisco
A30: 28 | B30: PEKERJAAN PEMBANGUNAN SUTT 150 KV JERANJANG – SEKOTONG DAN GI 150 KV JERANJANG EXT. (2LB) | C30: =337749700+297300+3217636000 -> 3555683000 | F30: KSO PT. PURNAMA INDONESIA – PT. KENCANA ALAM PUTRA | I30: Closing 10 November | K30: Lolos sampul 1
A31: 29 | B31: PEMBANGUNAN EXT 1 TR BAY TRAFO KE 4 150/20 KV 60 MVA GI CIKANDE LINGKUP JASA PEMASANGAN | C31: 51325500 | F31: PT INDEVCO GLOBAL | I31: Closing 4 Desember | K31: Tender ulang semua sudah disubmit ulang
A32: 30 | B32: PEMBANGUNAN GI 150 KV PAKNING | C32: 1995973400 | F32: PT SAPTA GUNA UTAMA | K32: Closing 15 Desember
A33: 31 | B33: PEMBANGUNAN BAY KOPLER 150 KV GI SAMBUTAN PT PLN (PERSERO) UNIT INDUK PENYALURAN DAN PUSAT PENGATUR BEBAN KALIMANTAN | C33: 276864600 | F33: PT. DISTRACO | K33: Closing 6 Desember, Distraco menang besok CDA
A34: 32 | B34: PEMBANGUNAN EXT 1 TR BAY TRAFO KE 3 150/20 KV 60 MVA GI PUNCAK ARDI MULYA II (GI MODERN) LINGKUP JASA PEMASANGAN | C34: 57130500 | F34: PT INDEVCO GLOBAL | I34: Closing 5 Desember | K34: Tender ulang semua sudah disubmit ulang
A35: 33 | B35: EXTENSION 1 BAY TRAFO 150/20KV NGORO (PEMASANGAN EXTENSION 1 BAY TRAFO 150/20KV NGORO) | C35: 281838100 | F35: PT. Purnama Indonesia, Binabuana Sewaka, Buanareksa | I35: Closing tgl 15 Desember | K35: Masih evaluasi sampul 1
A36: 34 | B36: PENGADAAN DAN PENGGANTIAN ISOLATOR KONDISI KRITIS TERSEBAR DI UNIT TRANSMISI JAWA BAGIAN TIMUR DAN BALI (PENGADAAN ISOLATOR KOMPOSIT) | C36: 1474722000 | F36: PT. Kencana Alam Putra, Purnama Indonesia | K36: Closing tgl 22 Desember, masih evaluasi
A37: 35 | B37: PENGADAAN DAN PEMASANGAN REAKTOR 70 KV GARDU INDUK RUTENG SISTEM FLORES | C37: 216170300 | F37: PT. Lembah Sentral Elektronindo, Mulya Jatra | I37: Closing tgl 19 Desember | K37: Lolos sampul 1
A38: 36 | B38: PENANGANAN TOWER T-73 DAN T-75 SUTT 70KV NONOHONIS – KEFAMENANU SISTEM TIMOR | C38: 121924300 | F38: PT. SINERGI PROPERTI PRATAMA | K38: Menunggu aproval Drawing
A39: 37 | B39: PENGOPERASIAN IBT 6 KRIAN | F39: PT. Buanareksa Binaperkasa | K39: Closing 29 Desember, Menunggu penawaran harga dari PLP
A40: 38 | B40: PEMASANGAN EXTENSION 1 BAY TRAFO 150/20 KV TULUNGAGUNG II | F40: PT. Global Twin Star | K40: Closing 10 Januari 2024, Menunggu penawaran harga dari PLP

Sheet Progress 2022
B1: Progres 2022 | C1: =SUM(C3:C21) -> 10164493393
A2: No | B2: Project Name | C2: Value excl. PPN | D2: Status | E2: CUSTOMER | F2: Desc | G2: Factory Promise | H2: Remarks Kontraktor | I2: Remarks Principle | J2: Remarks AI | K2: INSULATOR | L2: Remarks | M2: PIC | N2: Keterangan
A3: 1 | B3: Pengadaan dan Pemasangan Kapasitor di Gl Puger 1x25 Mvar (Tahap 2) | C3: 150385000 | D3: Sudah PO | E3: PT MAHAKAAM JAYA SEJAHTERA | F3: STRINGSET DAN HV CONNECTOR | H3: PO DP 20%, Kontraktor mau pick up barang disatu tempat (Gudang UGC) | J3: Baut sudah dikirim, Tanggal Giro 10 January 2023, FU Dita
A4: 2 | B4: PENGGANTIAN KAWAT PETIR ACSR MENJADI AS SUTT BANTUL-KLATEN; KENTUNGAN-MEDARI-SANGGRAHAN; BAWEN-SECANG-SANGGRAHAN; GODEAN-BANTUL; BAWEN-KLATEN | C4: 2127828100+C5 | D4: Sudah PO | E4: PT KARYA PUTRA GEMILANG / UPT Salatiga | F4: STRINGSET & FITTINGS | I4: SOA 224744 Material selesai tanggal 22-23 November 2022 | J4: Material sudah diambil 26 Desember 2022 GIRO tanggal 26 Maret 2023
A5: 3 | B5: PEKERJAAN PERBAIKAN ANOMALI JARINGAN DI UPT BANDUNG | C5: KHS | D5: Kontrak Payung sudah, Parsial pemesanan menunggu konfirmasi dari PLN | E5: CIPTA DAYA UTAMA, PT | F5: ACCESSORIES AS 55 & AS 70 | H5: Menunggu Approval drawing | J5: Perkiraan awal tahun 2023 FU mbak Laely, Nabil | L5: FU Mbak laely & Nabil | N5: Baru pengumuman pemenang
A6: 4 | B6: UPRATING BUSBAR 150 KV GI PINAYUNGAN | C6: 905947000 | D6: Sudah PO | E6: DUTA CAKRAWALA INDONESIA, PT | F6: Stringset&HVC | H6: Revisi drawing | J6: Material sudah dihitung lengkap dan sudah diambil, Cek sudah difinance tanggal 14 February 2023 | L6: FU Ikhbal
A7: 5 | B7: EXTENSION 1 LINE BAY GI 150KV PETROKIMIA UNTUK LAYANAN KTT PT SMELTING | C7: 135929980 | D7: Sudah PO | E7: GLOBAL TWIN STAR, PT | F7: Stringset&HVC | H7: Menunggu PO sudah final nego | J7: Barang sudah diambil GIRO tanggal 8 January 2023 FU Dita
A8: 6 | B8: PENGADAAN STRING SET EARTH WIRE AS 70 MM2 DAN JASA PENGGANTIAN STRING SET SERTA EARTH WIRE DI WILAYAH UPT PURWOKERTO | C8: 464025800 | D8: Sudah PO | E8: MEGA ALFARIZKI, PT | F8: Stringset | H8: Menunggu DP, Material selesai tgl 23/12/22 & 25/11/22 | J8: GIRO tanggal 15 January 2023, Material diambil tanggal 13 Desember 2022 FU Dita
A9: 7 | B9: PENGADAAN DAN JASA PENGGANTIAN DOUBLE STRING SET SERTA ISOLATOR 120 KN UNTUK SUTT 150 KV GOMBONG - RAWALO - KESUGIHAN T.35-99 | C9: 1809194400 | D9: Sudah PO | E9: CIPTA DAYA UTAMA, PT | F9: Stringset | H9: DP sudah masuk 30%, Material selesai tgl 04/11/22 | J9: Material sudah diambil tanggal 31 Oktober 2022 CEK baru tangal 28 February 2023 | L9: SOA 224785(28/10/2022) | N9: Cek perlu diganti
A10: 8 | B10: Pengadaan dan Jasa Penggantian String Set serta Isolator 120 kN untuk SUTT 150kV Purbalingga - Rawalo T.94-172 | C10: 3186135459 | D10: Sudah PO | E10: Perintis Sarana Elektrik, PT | F10: Pengadaan dan jasa | H10: Pembayaran Back to back | I10: Minta penawaran harga terbaru | J10: Material sudah di cek dan dihitung, material shackle sudah ready tanggal 30 Desember 2022, turnbuckle pengganti CDE QTY 360 PO Hariini dan material selesai tanggal 6 February 2023 Info ke sicame jangan pake sisa stock, Masih menunggu progres project Purbalingga - Rawalo | L10: PO Perintis Back to Back, INA sudah DP 20% ke Sicamindo, Material siap di pick up minggu ke 3 Desember 2022 di balaraja oleh kontraktor | N10: Pastikan material selesai kapan.
A11: 10 | B11: Additional JASA PENGGANTIAN TRAFO #2 GI 150 KV SEMANU | C11: 3585120 | D11: Sudah PO (2) | E11: GLOBAL TWIN STAR, PT | J11: Material sudah diambil tanggal 5 January 2023 Dita cek pembayaran harus sudah masuk tanggal 4 February 2023
A12: 11 | B12: JASA PENGGANTIAN TRAFO #2 GI 150 KV SEMANU | C12: 5949000 | D12: Sudah PO (2) | E12: GLOBAL TWIN STAR, PT | H12: Menunggu Approval Drawing, Kontraktor minta diskon | J12: Material sudah diambil tanggal 5 January 2023 Dita cek pembayaran harus sudah masuk tanggal 4 February 2023
A13: 12 | B13: Pengadaan SUTT 150KV Rawalo Star T01-55 | C13: 968389530 | D13: Sudah PO | E13: Perintis Sarana Elektrik, PT | H13: Minta harga diskon ke sicame, minta jasa ke kontraktor, Sudah DP 10%, Minta jadwal FAT | J13: Material sudah lengkap sisa pembayaran 467.421.140,47 (Termin 2)
A14: 13 | B14: PENGADAAN DAN PEMASANGAN KAPASITOR 1X50 MVAR GI 150KV PURWOSARI | C14: 16000000 | D14: Sudah PO | E14: Purnama Indonesia, PT | J14: Menunggu pembayaran, dan barang ready stock
A15: 14 | B15: PENGADAAN DAN PEMASANGAN RELAY BUSBAR PROTECTION DI GI 150KV LAGADAR, GI 150KV WAYANGWINDU, GITET 500KV BANDUNG SELATAN, GISTET 500KV SAGULING, GIS 150KV SIMPANG LIMA, DAN GI 150KV JEPARA | C15: 55740000 | D15: Menunggu Drawing MTU | E15: Kencana Alam Putra, PT | J15: Drawing untuk approval sudah diberikan ke Zaenal KAP, Tinggal menunggu respon
A16: 15 | B16: PENGADAAN DAN PENGGANTIAN GSW TERSEBAR DI WILAYAH ULTG KEDIRI DAN ULTG BABAT | C16: 1070328580 | D16: Sudah PO | E16: GLOBAL TWIN STAR, PT | F16: STRING SET | J16: SOA 224943 ( Dec 2022- Feb 2023), Material sudah dipick up, kekurangan material suspesion clamp (February) dan awar (January) Pak Dedy FU ke pak Teguh dan cek gudang alam GIRO tanggal 22 Maret 2023
A17: 16 | B17: PENGADAAN DAN PENGGANTIAN GSW TERSEBAR DI WILAYAH ULTG MADIUN | C17: 974998310 | D17: Sudah PO | E17: GLOBAL TWIN STAR, PT | F17: STRING SET | J17: SOA 224951 ( Dec 2022- Feb 2023), Material diambil parsial tanggal 17 January 2023 Suspension clamp dan Awar qty 350 pcs sisanya tanggal 17 February 2023 dan GIRO parsial yang pertama tanggal 21 Maret 2023 Cek bagian keuangan invoice PLP baru bisa diterbitkan jika sudah material semua selesai (setelah tgl 17 February 2023)
A18: 17 | B18: Pembangunan Ekstension 1 Line Bay Konsumen di GI 150kV Indoferro | C18: 112978000 | D18: Menunggu Kontrak | E18: Buanareksa Binaperkasa, PT | J18: Nabil FU ke buanareksa taggal 12 January 2023
A19: 18 | B19: Additional GIS Gunung Sari | C19: 35712614 | D19: Sudah PO | E19: Sastramas Estetika, PT | J19: SOA 20 January 2023 (PLP) Disk Insulator Ready stock (Kuarta) FU Dita
A20: 19 | B20: Perkuatan Proteksi Petir Tersebar Wilayah UPT Madiun | C20: 178000000 | D20: Menunggu Kontrak | E20: Persada Indah Muda, PT | J20: Menunggu approval drawing dari PLN
A21: 20 | B21: JASA PEMASANGAN MTU DI WILAYAH UPT PROBOLINGGO | C21: 91194600 | D21: Menunggu Approval Drawing | E21: Cahaya Karya Bersama, PT | J21: sedang menunggu revisi drawing dari principal untuk diajukan ulang ke PLN FU Euis
A22: 21 | B22: SUTT PLN UPT BEKASI | E22: Jati Mulia, PT - DUTA CAKRAWALA INDONESIA, PT | J22: Menunggu penawaran harga dari ALAM

Sheet Progres 2021
B1: Progres 2021
A2: No | B2: Project Name | C2: Value | D2: Status | E2: Nama Kontraktor | F2: Desc | G2: PLP Promise | H2: Remarks Kontraktor | I2: Remarks PLP | J2: Remarks AI | K2: INSULATOR | L2: Remarks | M2: PIC | N2: Keterangan
A3: 1 | B3: GI 150 kV Tawaeli | D3: Prospek | E3: NSU | F3: STRINGSET DAN HV CONNECTOR | H3: Update drawing dan harga sudah, menunggu nego Kontraktor dengan PLN | I3: - | J3: Menunggu informasi dari NSU drawing sudah diberikan ke kontraktor harusnya sudah di approval PLN, belum ngasih penawaran FU Pak Fuad | L3: Tunggu PO Kontraktor ke Alam | M3: Fuad | N3: menunggu info selanjutnya dari PLN
A4: 2 | B4: GI 150 kV Bunta | D4: Prospek | E4: NSU | F4: STRINGSET DAN HV CONNECTOR | H4: Update drawing dan harga sudah, menunggu nego Kontraktor dengan PLN | I4: - | J4: Menunggu informasi dari NSU drawing sudah diberikan ke kontraktor harusnya sudah di approval PLN | L4: Tunggu PO Kontraktor ke Alam | M4: Fuad | N4: surat pernyataan dari PLP, menunggu info selanjutnya dari PLN
A5: 3 | B5: TL 150kV TIP 12 PLN Smelter CNI Switchyard | D5: Prospek | E5: Owner : CNI | J5: Pak Fuad FU ke Bu Happy/Bu Zakhia | M5: Fuad | N5: Belum ada pengumuman dari PP, blm ada kabar
A6: 4 | B6: TL 150kV KID - Pakning Sec. 1, 2 & 3 | D6: Prospek | E6: Owner : Sumbagteng | J6: Pak Fuad FU ke Pak OktaPLN Sumbagteng | M6: Fuad | N6: FU Pak Fuad ke Pak Oktarico, pengumuan sec.3 saja (dihold)
A7: 5 | B7: Pengadaan Stringset dan Jasa Penggantian GSW Rantas dan Korosif SUTT 70kV KSBRU-RSDKL T.01 S/D T.103 Dan Antara Tower A76 - A86 SUTET 500kV Cirata - Deltamas 1-2 | C7: 314000000 | D7: Sudah PO | E7: Persada Indah Muda (Pak Pradana) | F7: Stringset | G7: 16 Juli 2021 | H7: DP dan Approval drawing sudah | J7: Material diambil 24 Aug 2021, cash + cover giro 31/12/2021 | M7: Fuad
A8: 3 | B8: PENGANTIAN GSW AS 55 (T.10-T.36) SUTT 150 KV CILEGON BARU - ASAHIMAS - POLYPRIMA | C8: 120000000 | D8: Sudah PO | E8: PT DUTA CAKRAWALA INDONESIA | G8: Akhir January 2022 | J8: Sudah DP, material selesai akhir January 2022
C22: =SUM(C3:C14) -> 434000000

Sheet Progress 2020
B1: Progress 2020
A2: No | B2: Project Name | C2: Nama Kontraktor | D2: Desc | E2: PLP Promise | F2: Remark Kontraktor | G2: Remarks PLP | H2: Remarks AI | I2: INSULATOR | J2: Remarks | K2: PIC | L2: Keterangan
A3: 1 | B3: 150KV GI LUWUK & TOILI | C3: Amanda | D3: STRINGSET DAN HV CONNECTOR, PROSES ANTRIAN | E3: DONE | F3: Tukar giro tanggal 2 Juni 2020 | H3: Pembayaran menggunakan giro, Giro sudah expired tgl 9 Maret 2020 , FU pak Fuad minggu depan tgl 15 Juni 2020 ke bu ratna | I3: PI 2 buah blm di ambil masih di marunda | J3: sudah 297 hari AR nya, bulan oktober sudah, november mencairkan cek tiap akhir bulan, FU Bag. Keu akhir bulan Desember 2020 dibayar januari 2021 | K3: Fuad | L3: 1. Sisa pembayaran 534 juta FU Pak Fuad untuk menanyakan kepastian pembayaran d bulan maret 2020, Cicil perbulan 100 jt (sudah masuk cicilan ke dua GI Toili) barang sudah diambil 2. PO Additional belum diambil (Nilai 32.128.800)
A4: 2 | B4: PAKET 2 BAY TRAFO BANDUNG | C4: Amanda | D4: STRINGSET DAN HV CONNECTOR | F4: Sudah PO untuk DP dibayar per GI, kontraktor mengajukan adendum untuk perpanjangan kontrak, PO Connector sudah, blm ada progres dari kontraktor. Akan membayar lagi bulan Juni | H4: FU Fuad, sudah ada approval drawing dari kontraktor, PO kontraktor sudah diterima, Invoice sudah dibuatkan tgl 2 April 2020 | I4: 120 FOG, 700 PCS | J4: approval drawing untuk connector dan string set sudah ada, AR nya 400, kontrak sudah lewat, belum ada update lagi | K4: Fuad | L4: 1. PO Stringset Purwodadi (DP Purwodadi 78 Juta sisa 182 juta). 2. PO Stringset Balapulang (Done) 3. PO Stringset Kesugihan (Done) 4. PO Connector Balapulang (Done) PO add belum lunas 5. PO Connector Kesugihan (Done)
A5: 3 | B5: GI 150 kV Air Raja | C5: K E | D5: STRINGSET DAN HV CONNECTOR | F5: dokumen penagihan sudah lengkap di Bag. Keuangan KE (0254) 394100 ext 144 (PIC. Pak Yapi) | G5: sudah dikirim | J5: Bag. Keuangan Kasih list AR KE ke pak aco | K5: Fuad | L5: - air raja dan add malimping tertunggak 860 juta dicicil selama 10 bulan (perbulan 86juta) - cicilan bulan mei 2021 sudah di bayar (75jt)
A6: 4 | B6: TL 150 kV Malimping Bayah | C6: K E | D6: Stringset & Ubolt | F6: dokumen penagihan sudah lengkap di Bag. Keuangan KE (0254) 394100 ext 144 (PIC. Pak Yapi) | G6: Sudah dikirim | J6: Bag. Keuangan Kasih list AR KE ke pak aco | K6: Fuad | L6: - retensi Rp.382.596.613, maret bayar Rp.267.116.372 sisa Rp.115.453.241 2021 - cicilan bulan mei 2021 sudah di bayar (75 jt)
A7: 5 | B7: Bay Kapasitor GI Tersebar | C7: KSO TDKK - Metrindo | D7: Stringset | L7: - belum bayar 258 juta (final qty belum selesai) - menunggu final cek dari PLN, di FU oleh Pak Samudra
A8: 6 | B8: TL Cisumdawu | C8: DSU | D8: Stringset | L8: - belum bayar 432 juta
A9: 7 | B9: GI Rum | C9: Pratama Tunas Nusantara | L9: - belum bayar 462 juta
A10: 8 | B10: GI 150 kV Sekotong | C10: Sastramas | D10: STRINGSET DAN HV CONNECTOR | F10: PLN sudah Approval, PO kontraktor sudah, invoice DP di bulan maret 2020, | G10: PLP sudah kirim AO due tgl 7 april 2020 | H10: Sudah PO | J10: Barang sudah diambil semua | K10: Fuad | L10: - sisa hutang nya 740 juta baru dicicil 1x (50juta)
A11: 9 | B11: GI Padang Sambian | C11: Sastramas | D11: STRINGSET DAN HV CONNECTOR | J11: Barang sudah diambil semua | K11: Fuad | L11: - belum bayar 273 juta janji habis lebaran, 17 Mei 2021
A12: 10 | B12: GI Ende Ruteng | C12: Sastramas | J12: Barang sudah diambil semua | K12: Fuad | L12: - belum bayar 82 juta
A13: 11 | B13: Komponen HWK App Purwokerto | C13: Pelita Bumi Wangi | D13: Komponen HWK | F13: *. Pembayaran di bulan maret 2020 tgl 10 maret jika blm ada akan memberikan giro | H13: FU pak Fuad | I13: - | K13: Fuad | L13: - kurang 101 juta Janji dibayar habis lebaran 17 Mei 2021
A14: 12 | B14: Sangata Maloy Sec. 1-3 | C14: Waskita Karya | D14: Stringset | E14: 16 Maret 2021 | K14: Bu Sari | L14: - Material tahap 1 sudah di kirimkan, Surat Delivery Time sudah diberikan dari PLP - material add akan dikirim bulan juni - addendum kontrak ttd waskita sudah diterima - cicilan sec.1 sudah dibayar 500jt bulan mei 2021
A15: 13 | B15: Relokasi KCIC DK 73 | C15: Dwipa Konektra | H15: Sudah PO Stringset ke PLP DK 73, Insulator belum PO menunggu approval dari WIKA | K15: Priyo | L15: menunggu pembayaran pelunasan dari dwipa dan pengambilan material nya
A16: 14 | B16: TL 150 KV Rengat Tembilahan 4 | C16: PT. Waskita Karya | D16: Stringset | H16: Pengiriman untuk material tgl 15 Oktober sudah dikirim | K16: Priyo | L16: - Barang add sudah dipacking - cicilan sudah dibayar 500jt
A17: 15 | B17: GI Manisrejo | C17: Purnama | D17: Stringset & Connector | K17: Priyo | L17: - Barang sudah digudang - DP belum (201 juta pelunasan 470 juta) - pembayaran giro jatuh tempo 22 Juni 2021 - cicilan pembayaran 50 jt bulan Mei 2021
A18: 16 | B18: Post Insulator 20kV | C18: Basuki | D18: Post Insulator | L18: - maret sudah bayar 200jt sisa 87jt
A19: 17 | J19: 83-866-054-458
A20: 18
C21: Very Urgent
C22: Urgent
C23: Standart

Sheet Next Project
B1: Next Project
A2: No | B2: No | C2: Project Name | D2: Desc | E2: Estimated Value (Rp) | F2: Kontraktor | G2: PIC | H2: Remark | I2: Target | J2: Keterangan
B3: 1
B4: 2
A5: 26 | B5: 3
A6: 27 | B6: 4
B7: 5
B8: 6
B9: 7
B10: 8
B11: 9
B12: 10
B13: 11
B14: 12
B15: 13
B16: 14
B17: 15
B18: 16
... B29: 27

Sheet Loss
A2: Project Loss
A4: No | B4: Project Name | C4: Nama Kontraktor | D4: Desc | E4: PLP Promise | F4: Remark Kontraktor | G4: Remak PLP | H4: Remarks | I4: PIC
A5: 1 | B5: GI 150 kV SUNYARAGI | C5: MPT | D5: DISC INSULATOR | E5: End of Desember 2019 | F5: Sudah ada penawaran dari Alam, diganti sediver | G5: - | H5: 120 FOG, 1250 PCS Menunggu Konfirmasi dari Pak Dyan | I5: Priyo
A6: 2 | B6: GI 150 kV SEMEN JAWA | C6: MPT | D6: STRINGSET DAN HV CONNECTOR | E6: End of Desember 2019 | F6: Menunggu penawaran dari Alam | G6: Tunggu penawaran dari PLP | H6: GANTI MEREK, Karena kita minta penawaran 24 april baru di berkan harga 9 juni | I6: Priyo
A7: 3 | B7: Relokasi 275 kv Pekanbaru | C7: Bekasap | D7: Stringset | F7: Menunggu Penawaran dari Alam (Priyo) FU pak priyo tgl 25/11/2019 | I7: Priyo
A8: 4 | B8: CISUMDAWU PHASE 4 | C8: CMS/DSU (Dede Sufthendy) | D8: STRINGSET ACSR 450/410 | F8: batal PO, email sudah , menunggu pembayaran 420 juta | H8: kebutuhan material : double tension yang kita punya 340, 450 (12 set) Insulator 300 pcs, Light weight spacer 200 crs for ACSR 450 15 pcs, dan spacer 400 crs ACSR 450 42 pcs koordinasi untuk leadtime kabelindo dan penambahan material outstrisd dan ACSR 120 material stok ACSR 340 tetapi harus diganti untuk double conductor menjadi single | I8: Aco
A9: 5 | B9: GI 150 kV SUMENEP | C9: PPWS | D9: STRINGSET DAN HV CONNECTOR | E9: End of Maret 2019 | F9: pak aco udh FU untuk pembayarannya karena copy invoice sudah di serahkan | H9: connector memakai produk lokal tidak PLP String dan konektor masih menunggu dari PLP (Drawing dan Penawaran) | I9: Aco
A10: 6 | B10: 150KV GI PAMEKASAN | C10: PPWS | D10: Connector | E10: Agustus 2019 | F10: hanya beli string set nya selesai, spacer blm bikin PO | H10: spacer masih ditanyakan ke pak dede, Crossceck PO terdahulu di keuangan Konektor masih menunggu konfirmasi Pak Dyan, belum di PO Konektor | I10: Aco
A11: 7 | B11: GI Balaraja | C11: GTS | D11: Stingset | F11: blm di approval jadi blm di bikin PO (blm ada Update) pak fuad FU minggu ini | H11: Pak Fuad FU minggu ini | I11: Fuad
A12: 8 | B12: GI Lengkong, GI Legok | D12: Stringset dan Conector | F12: Tender di ulang habis lebaran | G12: Menunggu Shoping list dari kontraktor | H12: menunggu meeting dgn PLP, hasilnya untuk meeting tgl 10 Maret 2020 di PLN Gandul Kontraktor belum kontrak dengan PLN, FU pak priyo ke pak wahyu | I12: Priyo
A13: 9 | B13: GI Tanjung Pura 150kV dan GI Samalanga | C13: Medan Smart Jaya | D13: ADSS+Join Box | G13: AO Sudah | H13: Barang sudah jadi, invoice dikirim 25 Februari 2020 | I13: Aco
A14: 10 | B14: Sorikmarapi | C14: Lumintu - Supraco | H14: Menunggu konfirmasi dari kontraktor, hari ini ada info dari Lumintu pak dunung | I14: Priyo
A15: 11 | B15: Proyek 150KV ACCC Kopenhagen Relokasi Tower KCIC | C15: EIP | H15: Harga Terlalu Mahal | I15: Aco
A16: 12 | B16: Kontraktor Cirebon | C16: PT Cipta Daya Utama | G16: Penawaran sudah tunggu PO | H16: Survei tgl 30 Juni 2020 | I16: Priyo
A17: 13 | B17: SUTT Wonosobo Secang, SUTT Jelok - Sanggrahan | C17: Stringset dan Insulator | D17: 3600000000 | E17: UPT Salatiga | F17: Priyo | G17: Pemenang Pelita Bumi Wangi
A18: 14 | B18: TL 150 Marisa - Moutong Sec.1&2 | C18: Stringset Insulator | E18: PT. KAP | F18: Priyo | G18: Dokumen kelengkapan tender sudah diberikan
A19: 15 | B19: Nusra 7 TL 5 GI | C19: Stringset Insulator | D19: 2200000000 | E19: KAP | F19: Priyo & Aco | G19: GI Bima Sape Lanjutan(KAP) kalah | H19: 44202 | I19: Ditunda Thn Depan
A20: 16 | B20: Relokasi KCIC DK 86 | E20: Dwipa | G20: Dwipa ke KPP
A21: 17 | B21: TL 150kV Tanjung Sari | E21: Alhas Jaya Group | F21: Priyo
A22: 18 | B22: GISTET Duri Kosambi 500kV dan GI 150kV Duri Kosambi | E22: PT Buana Reksa | F22: Fuad | G22: Pemenang Buanareksa pakai sicam | H22: 44202
A23: 19 | B23: TL 150kV Marunda Bekasi | C23: Tri Sinergi | H23: pake barang KAK (ready) | I23: Priyo
A24: 20 | B24: GIS 150 kV Ancol | C24: STRINGSET DAN HV CONNECTOR | E24: Lumintu | F24: Priyo | G24: dibatalkan sepihak oleh PLN
A25: 6 | B25: KCIC DK108 atau SUTT 150KV Purwakarta - Kosambi Baru Tol Japek 2 Sisi | C25: CMS | F25: Pemenang PT. CMS, menunggu pembayaran dari WIKA | H25: Menunggu info dari pak asep CMS, lahan belum bebas ditunda atau kemungkinan dibatalkan | I25: Fuad
A26: 8 | B26: Jatiluhur - Cikampek DK 130 & 132 | C26: Alhas | D26: Stringset & Insulator ( Dalian) | F26: menunggu approval drawing dari PLN E, PLN UIT Bandung | H26: - menunggu info konsinyering dari KCIC dan UIP Bandung, menunggu approval PLN E | I26: Fuad
A27: 8 | B27: Pengadaan dan Pemasangan MTU P0 Non Swakelola di UPT Gresik tahun 2021 | C27: 100000000 | D27: Menunggu Eksekusi Project | E27: PT MULYA JATRA | F27: HVC | H27: PLP/Sicame
A28: 12 | B28: Penggantian MTU KARAWANG | C28: 100000000 | D28: Loss, Balik ke IAG | E28: PT JATIMULIA INDONESIA | F28: HVC
A29: 7 | B29: PEMBANGUNAN BUS SECTION GI 150KV PAITON | C29: 100000000 | D29: Menunggu Eksekusi Project | E29: PT MULYA JATRA | F29: HVC | H29: info ke PLN | J29: menunggu revisi Drawing dari PLP
A30: 23 | B30: PENGGANTIAN KAWAT GSW SUTET 500 KV BALARAJA – LENGKONG – GANDUL DALAM RANGKA PENGGANTIAN GSW TERSEBAR PADA SALURAN TRANSMISI WILAYAH UPT CAWANG | D30: Menunggu kontrak | E30: Karya Putra Gemilang, PT | N30: KSO dengan Bira, Kemungkinan besar Bira sudah opeb PO ke distributor lain
A31: 24 | B31: PENGGANTIAN TRAFO KONDISI KRITIS PO TRAFO 2 70/20 KV GI KRACAK | C31: 50000000 | D31: Menunggu Kontrak | E31: INDEVCO GLOBAL, PT | J31: FU
A32: 9 | B32: JASA PENGGESERAN TRAFO DI GI 150KV BANARAN, GIS DRIYOREJO DAN GI 70KV DOLOPO (PEKERJAAN UPRATING IBT 1 DAN TINDAKLANJUT ANOMALI PENGGANTIAN TRAFO 4 GIS DRIYOREJO | C32: 24754900 | D32: Menunggu konfirmasi kontraktor | E32: Karyasembada Ciptamandiri, PT | J32: Kontraktor menunggu konfirmasi PLN terkait kesiapan material 6 minggu, Mbak Laely cari barang yang stock
A33: 14 | B33: PENYEMPURNAAN REKONFIGURASI SINGLE BUSBAR MENJADI DOUBLE BUSBAR GI BULUKANDANG (TAHAP 2) | C33: 300000000 | D33: Menunggu kontrak | E33: Kencana Alam Putra, PT | F33: String set & Insulator 120Fog | J33: Material pakai pabrikan sangdong
A34: 24 | B34: Insulator U120BP | C34: 5241100000 | E34: PT Alhas Jaya Group | L34: Minta dari negara OECD, minta penawaran harga ke La Granja | M34: Mbak Laely
A35: 6 | B35: SUTT PLN UPT BEKASI | E35: Jati Mulia, PT - DUTA CAKRAWALA INDONESIA, PT | J35: FU ke kontraktor penawaran harga alam,Jati Mulia belum dibalas ,DCI Mundur | L35: Fu nabil minggu ini | M35: Mbak Laely
A36: 28 | B36: Pengadaan Barang dan Jasa Konstruksi SUTT 150 kV Kubu – Amlapura Section 1 | C36: 2000000000 | E36: KSO CITRA RIANTARA - ALHAS JAYA GROUP, PT | J36: FU ganti ke Euis, Tidak jadi ikut karena HPS terlalu rendah
A37: 30 | B37: Pengadaan Barang dan Jasa Konstruksi SUTT 150 kV Kubu – Amlapura Section 3 | C37: 2000000000 | E37: KSO MAHAKAAM - ALHAS JAYA GROUP, PT | J37: FU ganti ke Euis, Tidak jadi ikut karena HPS terlalu rendah
A38: 39 | B38: Kabel Dropwire 2 & 4 Core | E38: Moratelindo,PT | I38: CCSI | M38: Pak Agus
A39: 14 | B39: Tender Material Non Rutin UPT Duri Kosambi | C39: 3303962991 | E39: PLN UPT Duri Kosambi, PT | J39: Pemenang tender SPE | M39: Dita
A40: 22 | B40: Jasa Pekerjaan Perbaikan Anomali Instalasi & tindak lanjut gangguan di UPT Bogor | C40: 1420000000 | E40: PLN UPT Bogor, PT | J40: Kalah tender, Pemenang PSE, INA missed di PPN | L40: closing 27 Januari 2023
A41: 26 | B41: Jasa Penggantian GSW korosif dan stringset pada SUTET 500 kv Cirata-Deltamas 2 span UPT Karawang | C41: 1674888000 | E41: PLN UPT Karawang, PT | J41: Pemenang tender PT. Arca | L41: closing 6 Februari 2023
A42: 27 | B42: Pembangunan GI 150 kV Pematang Siantar (Ext.) 2 LB Arah Tanah Jawa | C42: 400000000 | E42: Sapta Guna Utama, PT | J42: Pemenang PT. Elsewedy | L42: closing 23 January 2023
...

Sheet LATEST LOSS
A1: No | B1: Project Name | C1: Value excl. PPN | D1: Status | F1: CUSTOMER | G1: Desc | H1: Factory Promise | I1: Remarks Kontraktor | J1: Remarks Principle | K1: Remarks AI | L1: INSULATOR | M1: Remarks | N1: PIC | O1: Keterangan
A2: 29 | B2: PEMBANGUNAN GI 150/20 KV SOREK DAN INCOMER SUTT 150 KV | C2: =1494960280+618749219 -> 2113709499 | D2: 113000000000 | E2: pakai handal & hogn minta harga mereka | F2: PT. Sapta Guna Utama | K2: Closing tgl 27 Agustus, FU Ibu 9 sept (3 merk), pakai handal & hogn minta harga mereka
A3: 51 | B3: Pengadaan Alat Thermovisi GI Tersebar di UPT Bekasi | F3: PT. Indodaya Naratama Abadi | K3: Tidak submit, harga Flir tidak masuk HPS
A4: 52 | B4: Pengadaan dan Jasa Penggantian String Set serta Isolator untuk SUTT 70 kV Kedung Badak - Kracak Tahap 3 | F4: PT. Indodaya Naratama Abadi | K4: tidak lulus sampul 1, karna dok teknis data supply dari pabrikan & kontrak dan data personalia dan CV Pemenang spektrum 475 harga kita 503
A5: 53 | B5: Pengadaan dan Jasa Penggantian String Set serta Isolator untuk SUTT 70 kV Kedung Badak - Kracak Tahap 3 | F5: PT. Tuban Jaya Mandiri | K5: Closing 21 Nov (minta isolator Huble) kalah sampul 2
A6: 14 | B6: PENGADAAN ALAT UJI DI WILAYAH UPT BANDUNG | D6: HPS: 955.955.925 | F6: PT. INDODAYA NARATAMA ABADI | K6: Aanwijzing 19 des closing 15 January 25
A7: 36 | B7: Pekerjaan Pembangunan Extension 1 Trafo Bay + Trafo 30 MVA Gardu Induk 150 kV Satui | F7: PT. MEGA POWER TEKNINDO | K7: Closing 6 Desember, kalah sampul 1
A8: 38 | B8: PENGGANTIAN STRINGSET DAN ISOLATOR SUTT 150 KV JATILUHUR – PADALARANG TAHAP 1 | F8: PT. TUBAN JAYA MANDIRI, PT MEGA ALFARIZKI | K8: Mega alfa kalah sampul 2 , tuban tidak masukin penawaran
A9: 28 | B9: PENGADAAN DAN PENGGANTIAN MTU DI WILAYAH UPT SEMARANG | C9: 6011000000 | D9: Masatek
A10: 29 | B10: JASA PELAKSANAAN UPRATING BAY TRAFO GI 150 KV KE 2 SERONDOL | C10: 7041188000 | E10: DPT
A11: 32 | B11: PENGADAAN DAN PENGGANTIAN PROTEKSI BUSBAR DAN DIAMETER TERSEBAR DI WILAYAH UPT SEMARANG | C11: 5496945000 | D11: Masatek
A12: 34 | B12: PENINGKATAN KEANDALAN SALURAN TRANSMISI DI UIT JBB LINGKUP PENGGANTIAN KONDUKTOR DAN AKSESORIS DI UPT CILEGON | C12: 1163967360 | D12: Menunggu harga ACCC dari PLP, FU tgl 2 jan | F12: PT. Tuban Jaya Mandiri | H12: Pakai Ribe sesuai permintaan PLN | K12: Closing 19 Nov (minta isolator polymer, Huble) Tuban Menang, Nabil minta harga ke PLP untuk ACCC, kemarin nego harga
A13: 35 | B13: DPT MATERIAL ISOLATOR KERAMIK | D13: DPT | F13: PT. Kencana Alam Putra | K13: Closing 13 Des, klarifikasi sampul 1, gagal tidak ada sukses operasi 160kN dan sukses operasi dari UPT
A14: 39 | B14: PEKERJAAN MATERIAL UNTUK PEMERLIHARAAN DI WILAYAH UPT BOGOR | D14: HPS : 2.383.364.163 | F14: PT. INDODAYA NARATAMA ABADI | K14: Aanwijzing 19 des closing 8 January 25 Kalah sampul 1 PG Clamp tidak ada surat dukungan
A15: 42 | B15: PEKERJAAN PEMELIHARAAN PERALATAN ME DI GEDUNG THAMRIN KOPERBI JAKARTA | K15: gagal mengikuti karena tidak ada BPJS
A16: 7 | B16: PENGADAAN DAN PEMASANGAN REAKTOR 70 KV GARDU INDUK RUTENG SISTEM FLORES | C16: 216170300 | E16: 4 okt baru mulai sipilnya estimasi 3-4 bulan oct ini renc survey | F16: PT. Lembah Sentral Elektronindo | I16: Closing tgl 19 Desember, dalam masa sanggah, PLN terbitin surat pemenang | K16: status masih masih ada permntaan insulator Glass, PO akan diliris Feb-Maret, diinfokan ke kontraktor kemungkinan harga naik didatangin tgl 09 jan 25, tdk pakai PLP
A17: 30 | B17: PERKUATAN SISTEM PROTEKSI PETIR TERSEBAR DI WILAYAH UPT SEMARANG | C17: 8196840000 | D17: yg punya PWS, Pinjem bendera CKB pakainya Handal | E17: DPT
A18: 41 | B18: PENGADAN KABEL ON SHORE CONNECTION JETTY | C18: 8221900000 | F18: PT. INDODAYA NARATAMA ABADI | K18: kalah harga 1 : Jembo 6.577.520.000 2. 6.577.675.000 MKN 3 6.775.000.000 Voksel
A19: 43 | B19: PERABOT NON LOGAM ECATALOGUE 2024 | C19: 9936220500 | K19: yg lolos hanya Ruhui INA tdk lolos : 1 warna harusnya hitam hasil uji test tiap kursi
A20: 46 | B20: PEMBANGUNAN TRANSMISI 150 KV CIKUPA NEW – INC. (TERMASUK TOWER TX JATAKE – JATAKE II) | C20: 899987312 | F20: PT. KRAKATAU ENGINEERING & CONSTRUCTION | K20: Pemasukan 17 Januari Kalah sampul 1 update di eproc tidak masukan
A21: 48 | B21: PENGADAAN STRING SET EARTH WIRE AS 70 MM2 DAN JASA PENGGANTIAN STRING SET SERTA EARTH WIRE SUTT 150 KV KALIBAKAL-RAWALO-PLTU CILACAP T.01- 44 | C21: 742329430 | F21: PT MEGA ALFARIZKI | K21: Closing 23 Januari kalah yg menang Pelita Bumi Wangi pakai sicame
A22: 52 | B22: PEMBANGUNAN EXTENSION 2 LINE BAY GI 150 KV BALONGAN DAN PENYEMPURNAAN GI 150 KV BALONGAN | C22: 1568027310 | F22: KSO QDC – Buanareksa | K22: Closing 5 Feb, kalah harga pemenang Bisetta
A23: 24 | B23: Penambahan Grounding Langsung di UIT JBB Lingkup Penambahan Grounding di UPT Pulogadung pada SUTET 500 KV Tambun – Bekasi – Muara Tawar | C23: 188511200 | F23: PT. Tuban Jaya Mandiri | I23: Closing 4 Oktober | K23: Closing 4 Oktober, menunggu BA nego, sdh ttd kontrak 12 nov, mengajukan approval dwg ada beberapa pertanyaan ditgl 2 des, sdh dikirim pengajuan buat approval sdh survey kemungkinan pek. Awal tahun, ada perubahan design tidak pakai PLP
A24: 27 | B24: PEMBANGUNAN GI 150 KV JATILUHUR BARU | C24: 2347495545 | F24: PT. High Volt Technology | K24: Closing Jan, FU kalah pemenang WST
A25: 30 | B25: Penggantian Stringset dan Isolator Switchyard di GIS Salak Lama, GI Bogor Baru, dan GI Cileungsi | F25: PT. Tuban Jaya Mandiri | K25: Closing : 26 Feb, kalah harga pemenang Pandan Wangi
A26: 33 | B26: PEMBANGUNAN GARDU INDUK 150 KV KTT INDAH KIAT | C26: 1530336855 | F26: KONSORSIUM KAP – MJSU, PT. POWERCHINA INTELIGENSI DAN INTEGRITAS ENERGI TEKNOLOGI INDONESIA, PT. Niagamas Setiausaha | K26: Closing 22 Januari, kalah harga pemenang WST, KAP harga ke-2
A27: 34 | B27: Tender Ulang Pekerjaan Pembangunan Extension 1 Trafo Bay + Trafo 30 MVA Gardu Induk 150 kV Satui | C27: 224493100 | F27: PT. MEGA POWER TEKNINDO | K27: Closing 30 Januari 2025, Kalah harga pemenang Citra Bakti Persada
A28: 36 | B28: PENGADAAN STRING SET EARTH WIRE AS 70 MM2 DAN JASA PENGGANTIAN STRING SET SERTA EARTH WIRE SUTT 150 KV MRICA-WONOSOBO 1,2 T.1-108, SUTT 150 KV MRICA-PURBALINGGA 2 T.1-78 | C28: 1305633735 | F28: PT MEGA ALFARIZKI | K28: Closing 8 Feb, kalah harga pemenang pelita bumiwangi
A29: 37 | B29: PENGGANTIAN STRINGSET DAN ISOLATOR KOROSIF SUTT CIGERELENG – RAJAMANDALA – SUKALUYU – CIANJUR TAHAP 1 | C29: 282652500 | F29: PT. Kilat Wahana Jenggala | K29: Closing 20 Feb, kalah harga pemenang Global Twin Star
A30: 38 | B30: PEMASANGAN MULTI DIRECT GROUNDING (MDG) SUTT 70 DAN 150 KV TERSEBAR WILAYAH UPT BOGOR | C30: 2427276000 | F30: PT. Tuban Jaya Mandiri, PT Tesla Daya Elektrika | K30: Closing 24 Feb, TJM menang tidak pakai PLP pakainya KAK
A31: 39 | B31: PENGADAAN STRING SET EARTH WIRE AS 120MM2 DAN JASA PENGGANTIAN STRING SET SERTA EARTH WIRE SUTET 500 KV MANDIRANCAN – PEMALANG 1 T. 125-198 | C31: 462321680 | F31: PT MEGA ALFARIZKI | K31: Closing 25 Feb, kalah harga pemenang perintis sarana elektrik
A32: 42 | B32: PENGGANTIAN STRINGSET DAN ISOLATOR KOROSIF GI TERSEBAR DI WILAYAH UPT BANDUNG | F32: PT DUTA CAKRAWALA INDONESIA | K32: Closing 7 Maret, kalah harga pemenang GTS
A33: 30 | B33: PENGGANTIAN CT 500 KV P0 DI WILAYAH UPT BEKASI | C33: 147385728 | F33: PT DUTA CAKRAWALA INDONESIA | K33: Closing 10 Maret, Menang tdk pakai PLP
A34: 34 | B34: MODIFIKASI PENTANAHAN TOWER DI WILAYAH UPT PULOGADUNG TAHUN 2025 | K34: Closing 10 April, batak pemasukan, karna harga diatas pagu
A35: 3 | B35: PERKUATAN SISTEM PROTEKSI PETIR TERSEBAR DI WILAYAH UPT SEMARANG | C35: 8196840000 | K35: Tender terbatas, pemenang CKB
A36: 6 | B36: PEMBANGUNAN GI 150 KV JATILUHUR BARU | C36: 2347495545 | F36: PT. High Volt Technology
